not.throw.even.after.catch=''{0}'' を catch したのに throw していません。
